<mujoco model="arm3d">
    <compiler angle="radian" coordinate="local" inertiafromgeom="true" meshdir="." texturedir="." />
    <option gravity="0 0 0" integrator="Euler" iterations="20" timestep="0.01" />

    <default>
        <joint armature="0.04" damping="1" limited="true" />
        <geom conaffinity="0" condim="1" contype="0" density="10" friction=".8 .1 .1" margin="0.002" />
    </default>

    <worldbody>
        <light diffuse=".5 .5 .5" dir="0 0 -1" pos="0 0 3" />

        <geom material="table_material" conaffinity="1" contype="1" name="table" pos="0 0.5 -0.325" size="10 10 0.1" type="plane" />

        <body name="wrist base" pos="0. 0. -0.2930">
            <joint axis="0 1 0" damping="0.1" name="wrist_slidey" pos="0 0 0" range="-10.3213 10.3" type="slide" />
            <joint axis="1 0 0" damping="0.1" name="wrist_slidex" pos="0 0 0" range="-10.3213 10.3" type="slide" />
            <joint axis="0 0 1" damping="0.5" name="wrist_hinge" pos="0 0 0" range="-10.3213 10.3" type="hinge" />
            
            <geom conaffinity="1" contype="1" fromto="0 0.04 0. 0 -0.04 0" size="0.02" type="capsule" />
            <geom conaffinity="1" contype="1" fromto="0 0.04 0. 0.06 0.1 0" size="0.02" type="capsule" />
            <geom conaffinity="1" contype="1" fromto="0 -0.04 0. 0.06 -0.1 0" size="0.02" type="capsule" />
            <geom conaffinity="1" contype="1" fromto="0 0.04 0. -0.06 0.1 0" size="0.02" type="capsule" />
            <geom conaffinity="1" contype="1" fromto="0 -0.04 0. -0.06 -0.1 0" size="0.02" type="capsule" />
            
            
            
            <geom conaffinity="1" contype="1" fromto="0.06 -0.1 0. 0.12 -0.1 0" size="0.02" type="capsule" />
            <geom conaffinity="1" contype="1" fromto="0.06 .1 0. 0.12 0.1 0" size="0.02" type="capsule" />
            <geom conaffinity="1" contype="1" fromto="-0.06 -0.1 0. -0.12 -0.1 0" size="0.02" type="capsule" />
            <geom conaffinity="1" contype="1" fromto="-0.06 .1 0. -0.12 0.1 0" size="0.02" type="capsule" />
            
            
            <geom conaffinity="1" contype="1" fromto="0 0.04 0.05 0 -0.04 0.05" size="0.02" type="capsule" />
            <geom conaffinity="1" contype="1" fromto="0 0.04 0.05 0.06 0.1 0.05" size="0.02" type="capsule" />
            <geom conaffinity="1" contype="1" fromto="0 -0.04 0.05 0.06 -0.1 0.05" size="0.02" type="capsule" />
            <geom conaffinity="1" contype="1" fromto="0 0.04 0.05 -0.06 0.1 0.05" size="0.02" type="capsule" />
            <geom conaffinity="1" contype="1" fromto="0 -0.04 0.05 -0.06 -0.1 0.05" size="0.02" type="capsule" />
            
            <geom conaffinity="1" contype="1" fromto="0.06 -0.1 0.05 0.12 -0.1 0.05" size="0.02" type="capsule" />
            <geom conaffinity="1" contype="1" fromto="0.06 .1 0.05 0.12 0.1 0.05" size="0.02" type="capsule" />
            <geom conaffinity="1" contype="1" fromto="-0.06 -0.1 0.05 -0.12 -0.1 0.05" size="0.02" type="capsule" />
            <geom conaffinity="1" contype="1" fromto="-0.06 .1 0.05 -0.12 0.1 0.05" size="0.02" type="capsule" />

            <geom conaffinity="1" contype="1" fromto="0.06 -0.1 0. 0.06 -0.1 0.05" size="0.02" type="capsule" />
            <geom conaffinity="1" contype="1" fromto="0.06 0.1 0. 0.06 0.1 0.05" size="0.02" type="capsule" />
            <geom conaffinity="1" contype="1" fromto="-0.06 -0.1 0. -0.06 -0.1 0.05" size="0.02" type="capsule" />
            <geom conaffinity="1" contype="1" fromto="-0.06 0.1 0. -0.06 0.1 0.05" size="0.02" type="capsule" />
           
            
            
            
            <geom conaffinity="1" contype="1" fromto="0. -0.04 0. 0. -0.04 0.05" size="0.02" type="capsule" />
            <geom conaffinity="1" contype="1" fromto="0 0.04 0. 0. 0.04 0.05" size="0.02" type="capsule" />

            <geom conaffinity="1" contype="1" fromto="0.12 0.1 0. 0.12 0.1 0.05" size="0.02" type="capsule" />
            <geom conaffinity="1" contype="1" fromto="0.12 -0.1 0. 0.12 -0.1 0.05" size="0.02" type="capsule" />
            <geom conaffinity="1" contype="1" fromto="-0.12 0.1 0. -0.12 0.1 0.05" size="0.02" type="capsule" />
            <geom conaffinity="1" contype="1" fromto="-0.12 -0.1 0. -0.12 -0.1 0.05" size="0.02" type="capsule" />
        </body>
        
        
        <body name="obj1" pos="0.4 -0.4 -0.325">
            <geom density="0.001" mesh="object_mesh0" contype="1" conaffinity="1" type="mesh" rgba="0.1 0.3 0.4 1"/>
            <joint axis="0 1 0" damping="1.5" name="obj1_slidey" pos="0 0 0.05" range="-10.3213 10.3" type="slide" />
            <joint axis="1 0 0" damping="1.5" name="obj1_slidex" pos="0 0 0.05" range="-10.3213 10.3" type="slide" />
          <!--   <geom conaffinity="1" contype="1" pos="0 0 0.05" density="0.001" size="0.05 0.05 0.05" rgba="1 1 1 1" type="box" /> -->
        </body>
        
        
  

        <body name="obj2" pos="0.4 -0.2 -0.325">
            <geom density="0.001" mesh="object_mesh1" contype="1" conaffinity="1" type="mesh" rgba=".5 .5 .5 1"/>
            <joint axis="0 1 0" damping="1.5" name="obj2_slidey" pos="0 0 0.05" range="-10.3213 10.3" type="slide" />
            <joint axis="1 0 0" damping="1.5" name="obj2_slidex" pos="0 0 0.05" range="-10.3213 10.3" type="slide" />
            <!-- <geom conaffinity="1" contype="1" pos="0 0 0.05" density="0.001" size="0.05 0.05 0.05" rgba="1 1 1 1" type="box" /> -->
        </body>

        <body name="obj3" pos="0.4 0. -0.325">
            <geom density="0.001" pos="0. 0. 0" mesh="object_mesh2" contype="1" conaffinity="1" type="mesh" rgba="1 .75 .75 1"/>
            <joint axis="0 1 0" damping="1.5" name="obj3_slidey" pos="0 0 0.05" range="-10.3213 10.3" type="slide" />
            <joint axis="1 0 0" damping="1.5" name="obj3_slidex" pos="0 0 0.05" range="-10.3213 10.3" type="slide" />
            <!-- <geom conaffinity="1" contype="1" pos="0 0 0.05" density="0.001" size="0.05 0.05 0.05" rgba="1 1 1 1" type="box" /> -->
        </body>

        <body name="obj4" pos="0.4 0.2 -0.325">
            <geom density="0.001" pos="-0.1 -0.1 0" mesh="object_mesh3" contype="1" conaffinity="1" type="mesh" rgba="1 0 1 1"/>
            <joint axis="0 1 0" damping="1.5" name="obj4_slidey" pos="0 0 0.05" range="-10.3213 10.3" type="slide" />
            <joint axis="1 0 0" damping="1.5" name="obj4_slidex" pos="0 0 0.05" range="-10.3213 10.3" type="slide" />
            <!-- <geom conaffinity="1" contype="1" pos="0 0 0.05" density="0.001" size="0.05 0.05 0.05" rgba="1 1 1 1" type="box" /> -->
        </body>

        <body name="obj5" pos="0.4 0.4 -0.255">
            <geom density="0.001" mesh="object_mesh4" contype="1" conaffinity="1" type="mesh" rgba="1 .2 .2 1"/>
            <joint axis="0 1 0" damping="1.5" name="obj5_slidey" pos="0 0 0.05" range="-10.3213 10.3" type="slide" />
            <joint axis="1 0 0" damping="1.5" name="obj5_slidex" pos="0 0 0.05" range="-10.3213 10.3" type="slide" />
            <!-- <geom conaffinity="1" contype="1" pos="0 0 0.05" density="0.001" size="0.05 0.05 0.05" rgba="1 1 1 1" type="box" /> -->
        </body>

        <body name="obj6" pos="-0.4 -0.4 -0.325">
            <geom density="0.001" mesh="object_mesh5" contype="1" conaffinity="1" type="mesh" rgba=".0 .0 .0 1"/>
            <joint axis="0 1 0" damping="1.5" name="obj6_slidey" pos="0 0 0.05" range="-10.3213 10.3" type="slide" />
            <joint axis="1 0 0" damping="1.5" name="obj6_slidex" pos="0 0 0.05" range="-10.3213 10.3" type="slide" />
            <!-- <geom conaffinity="1" contype="1" pos="0 0 0.05" density="0.001" size="0.05 0.05 0.05" rgba="1 1 1 1" type="box" /> -->
        </body>


        <body name="obj7" pos="-0.4 -0.2 -0.325">
            <geom density="0.001" pos="0.3 -0.15 0" mesh="object_mesh6" contype="1" conaffinity="1" type="mesh" rgba="0 0 1. 1"/>
            <joint axis="0 1 0" damping="1.5" name="obj7_slidey" pos="0 0 0.05" range="-10.3213 10.3" type="slide" />
            <joint axis="1 0 0" damping="1.5" name="obj7_slidex" pos="0 0 0.05" range="-10.3213 10.3" type="slide" />
            <!-- <geom conaffinity="1" contype="1" pos="0 0 0.05" density="0.001" size="0.05 0.05 0.05" rgba="1 1 1 1" type="box" /> -->
        </body>

        <body name="obj8" pos="-0.4 0. -0.325">
            <geom density="0.001" pos="0.06 0.1 0" mesh="object_mesh7" contype="1" conaffinity="1" type="mesh" rgba="0 1 0 1"/>
            <joint axis="0 1 0" damping="1.5" name="obj8_slidey" pos="0 0 0.05" range="-10.3213 10.3" type="slide" />
            <joint axis="1 0 0" damping="1.5" name="obj8_slidex" pos="0 0 0.05" range="-10.3213 10.3" type="slide" />
            <!-- <geom conaffinity="1" contype="1" pos="0 0 0.05" density="0.001" size="0.05 0.05 0.05" rgba="1 1 1 1" type="box" /> -->
        </body>

        <body name="obj9" pos="-0.4 0.2 -0.325">
            <geom density="0.001" mesh="object_mesh8" contype="1" conaffinity="1" type="mesh" rgba="1 1 1 1"/>
            <joint axis="0 1 0" damping="1.5" name="obj9_slidey" pos="0 0 0.05" range="-10.3213 10.3" type="slide" />
            <joint axis="1 0 0" damping="1.5" name="obj9_slidex" pos="0 0 0.05" range="-10.3213 10.3" type="slide" />
            <!-- <geom conaffinity="1" contype="1" pos="0 0 0.05" density="0.001" size="0.05 0.05 0.05" rgba="1 1 1 1" type="box" /> -->
        </body>

        <body name="obj10" pos="-0.4 0.4 -0.325">
            <geom density="0.001" mesh="object_mesh9" contype="1" conaffinity="1" type="mesh" rgba=".6 .25 .25 1"/>
            <joint axis="0 1 0" damping="1.5" name="obj10_slidey" pos="0 0 0.05" range="-10.3213 10.3" type="slide" />
            <joint axis="1 0 0" damping="1.5" name="obj10_slidex" pos="0 0 0.05" range="-10.3213 10.3" type="slide" />
            <!-- <geom conaffinity="1" contype="1" pos="0 0 0.05" density="0.001" size="0.05 0.05 0.05" rgba="1 1 1 1" type="box" /> -->
        </body>

        
        <body name="target" pos="0.0 0. -0.375">
            <geom conaffinity="0" contype="0" pos="0 0 0.05" density="0.001" size="0.05 0.05 0.001" rgba="1. 0. 0. 1" type="box" />
        </body>
        
     <!--      
        <body name="goal1" pos="0.9 0.0 -0.3230">
            <geom conaffinity="0" contype="0" density="0.00001" rgba="1. 0. 0. 1" size="0.1 0.6 0.0005" type="box" />
        </body>

        <body name="goal2" pos="-0.9 0.0 -0.3230">
            <geom conaffinity="0" contype="0" density="0.00001" rgba="1. 0. 0. 1" size="0.1 0.6 0.0005" type="box" />
        </body> 
    -->
    </worldbody>
    <asset >
        <mesh file="meshes/mug.stl" scale="0.0014419716113 0.0014419716113 0.0014419716113" name="object_mesh0"/>
        <mesh file="meshes/candle_holder.stl" scale="0.00221564763838 0.00221564763838 0.00221564763838" name="object_mesh1"/>
        <mesh scale="0.00391787640326 0.00391787640326 0.00391787640326" name="object_mesh2" file="meshes/Rook.stl"/>
        <mesh file="meshes/fox.stl" scale="0.00138148311578 0.00138148311578 0.00138148311578" name="object_mesh3"/>
        <mesh file="meshes/Gengar.stl" scale="0.000210652537981 0.000210652537981 0.000210652537981" name="object_mesh4"/>
        <mesh file="meshes/vase1.stl" scale="0.000775193841988 0.000775193841988 0.000775193841988" name="object_mesh5"/>
        <mesh file="meshes/Trophy.stl" scale="0.00449730778558 0.00449730778558 0.00449730778558" name="object_mesh6"/>
        <mesh file="meshes/cupcake.stl" scale="0.00191879658518 0.00191879658518 0.00191879658518" name="object_mesh7"/>
        <mesh file="meshes/Pawn.stl" scale="0.00338627830315 0.00338627830315 0.00338627830315" name="object_mesh8"/>
        <mesh name="object_mesh9" file="meshes/Love_Box_1.stl" scale="0.001411430619914 0.00141430619914 0.00211430619914"/>
        <texture file="table/wood-texture/pic_002.png" name="table_texture" type="2d" />
        <material name="table_material" shininess="0.1" specular="0.4" texrepeat="1 1" texture="table_texture" />
    </asset>
    <actuator>
        <!-- <motor ctrllimited="true" ctrlrange="-2.0 2.0" joint="r_shoulder_pan_joint" /> -->
        <!-- <motor ctrllimited="true" ctrlrange="-2.0 2.0" joint="r_shoulder_lift_joint" /> -->
        <!-- <motor ctrllimited="true" ctrlrange="-2.0 2.0" joint="r_upper_arm_roll_joint" /> -->
        <!-- <motor ctrllimited="true" ctrlrange="-2.0 2.0" joint="r_elbow_flex_joint" /> -->
        <!-- <motor ctrllimited="true" ctrlrange="-2.0 2.0" joint="r_forearm_roll_joint" /> -->
        <motor ctrllimited="true" ctrlrange="-2.0 2.0" joint="wrist_slidex" />
        <motor ctrllimited="true" ctrlrange="-2.0 2.0" joint="wrist_slidey" />
        <motor ctrllimited="true" ctrlrange="-2.0 2.0" joint="wrist_hinge" />
    </actuator>
    

</mujoco>
